Workbook

Sheet Assignment
B1: Pricing Associate Case Study
B3: Context
B4: You are a Pricing Analyst. You have been tasked with analysing a cohort of ~800 household customers to understand how profitable this group is, identify patterns, and surface any relevant observations for the pricing team.
B6: Tasks
B7: 1 | C7: Data Preparation: Inspect the dataset carefully. In case you find data quality issues, flag them and consider whether this data is helpful
B8: 2 | C8: Customer-level Profitability: Calculate the total profit per customer per contract in two ways: a) In absolute terms (€) b) In relative terms (cents/kWh)
B9: 3 | C9: Create a summary with the key figures describing this customer cohort. Use your judgement on what is relevant, there is no single right answer!
B10: 4 | C10: How does profitability evolve across contract start months? Describe what you observe and raise at least one hypothesis that could explain the pattern, drawing on common sense and your understanding of the energy market
B11: 5 | C11: Which group of customers appears most and least profitable? Describe patterns you see and raise at least one hypothesis to explain them, drawing on common sense and your understanding of the energy market
B13: Definitions
B14: customer_ID | C14: Each Customer ID represents a single residential household
B15: contract_duration_months | C15: The number of month in which a customer is bound to a contract. We ofer mainly 2 contracts. They're named Fix12 (12 months duration) and Fix24 (24 months duration
B16: Aquisition channel | C16: The specific channel throught which the customers as offered a tariff and was given a contract
B17: Monthly consumption (kWh) | C17: The amount of electricity consumed by the household in a given month.
B18: Monthly bill (€, brutto) | C18: The total amount invoiced to the customer, including VAT (Mehrwertsteuer). Company applies a VAT rate of 19%
B19: Procurement cost (cents /kWh) | C19: The cost Company pays to source the electricity delivered to the customer
B20: Profit (to be calculated) | C20: The difference between what Company earns from the customer and what Company pays to procure the electricity
B22: Guidelines and TIPS
B23: No Powerpoint or presentation needed; limit your work entirely to Excel
B24: Use your critical thinking to decide which data is relevant and which entries should be discarted
B25: Feel free to decide on the format of your answers
B26: There is no single correct answer; We are interested in how you think, not just the numbers!
B27: Time cap for this exercise is: approximately 4 hours. If you find yourself taking much longer, wrap up with your findinds and explain what blockers your found
B28: You'll be asked to present your findinds, keep that in mind when deciding on format and content

Sheet Data
A1: customer_id | B1: contract_duration_months | C1: consumption_tier | D1: acquisition_channel | E1: contract_start_date | F1: monthly_consumption_kwh | G1: BRUTTO_monthly_bill_eur | H1: NETTO_procurement_cost_ct_per_kwh | I1: NETTO_monthly_revenue(€) | J1: procurement_cost_(€) | K1: ptofit_(€) | L1: profit_(ct/kWh) | M1: contract_start_month | N1: net_revenue_(€)
A2: C0001 | B2: 12 | C2: mid | D2: Check24 | E2: 24.04.2024 | F2: 199 | G2: 76.88 | H2: 24.21 | I2: =Table1[[#This Row],[BRUTTO_monthly_bill_eur]]/1.19 -> 64.605042 | J2: =Table1[[#This Row],[monthly_consumption_kwh]]*Table1[[#This Row],[NETTO_procurement_cost_ct_per_kwh]]/100 -> 48.1779 | K2: =Table1[[#This Row],[NETTO_monthly_revenue(€)]]-Table1[[#This Row],[procurement_cost_(€)]] -> 16.427142 | L2: =IF(F2=0,"",K2/F2*100) -> 8.2548452 | M2: =TEXT(E2,"yyyy-mm") -> 24.04.2024 | N2: =G2/1.19 -> 64.605042
A3: C0002 | B3: 24 | C3: low | D3: Check24 | E3: 26.01.2024 | F3: 110 | G3: 49.75 | H3: 30.01 | I3: =Table1[[#This Row],[BRUTTO_monthly_bill_eur]]/1.19 -> 41.806723 | J3: =Table1[[#This Row],[monthly_consumption_kwh]]*Table1[[#This Row],[NETTO_procurement_cost_ct_per_kwh]]/100 -> 33.011 | K3: =Table1[[#This Row],[NETTO_monthly_revenue(€)]]-Table1[[#This Row],[procurement_cost_(€)]] -> 8.7957227 | L3: =IF(F3=0,"",K3/F3*100) -> 7.9961115 | M3: =TEXT(E3,"yyyy-mm") -> 26.01.2024 | N3: =G3/1.19 -> 41.806723
A4: C0003 | B4: 24 | C4: mid | D4: Check24 | E4: 08.10.2024 | F4: 205 | G4: 85.14 | H4: 22.78 | I4: =Table1[[#This Row],[BRUTTO_monthly_bill_eur]]/1.19 -> 71.546218 | J4: =Table1[[#This Row],[monthly_consumption_kwh]]*Table1[[#This Row],[NETTO_procurement_cost_ct_per_kwh]]/100 -> 46.699 | K4: =Table1[[#This Row],[NETTO_monthly_revenue(€)]]-Table1[[#This Row],[procurement_cost_(€)]] -> 24.847218 | L4: =IF(F4=0,"",K4/F4*100) -> 12.120594 | M4: =TEXT(E4,"yyyy-mm") -> 08.10.2024 | N4: =G4/1.19 -> 71.546218
A5: C0004 | B5: 24 | C5: mid | D5: Check24 | E5: 07.09.2024 | F5: 226 | G5: 84.24 | H5: 25.44 | I5: =Table1[[#This Row],[BRUTTO_monthly_bill_eur]]/1.19 -> 70.789916 | J5: =Table1[[#This Row],[monthly_consumption_kwh]]*Table1[[#This Row],[NETTO_procurement_cost_ct_per_kwh]]/100 -> 57.4944 | K5: =Table1[[#This Row],[NETTO_monthly_revenue(€)]]-Table1[[#This Row],[procurement_cost_(€)]] -> 13.295516 | L5: =IF(F5=0,"",K5/F5*100) -> 5.8829717 | M5: =TEXT(E5,"yyyy-mm") -> 07.09.2024 | N5: =G5/1.19 -> 70.789916
A6: C0005 | B6: 12 | C6: mid | D6: Website | E6: 16.08.2024 | F6: 178 | G6: 70.68 | H6: 24.71 | I6: =Table1[[#This Row],[BRUTTO_monthly_bill_eur]]/1.19 -> 59.394958 | J6: =Table1[[#This Row],[monthly_consumption_kwh]]*Table1[[#This Row],[NETTO_procurement_cost_ct_per_kwh]]/100 -> 43.9838 | K6: =Table1[[#This Row],[NETTO_monthly_revenue(€)]]-Table1[[#This Row],[procurement_cost_(€)]] -> 15.411158 | L6: =IF(F6=0,"",K6/F6*100) -> 8.6579539 | M6: =TEXT(E6,"yyyy-mm") -> 16.08.2024 | N6: =G6/1.19 -> 59.394958
A7: C0006 | B7: 12 | C7: mid | D7: Website | E7: 22.05.2024 | F7: 253 | G7: 94.37 | H7: 25.35 | I7: =Table1[[#This Row],[BRUTTO_monthly_bill_eur]]/1.19 -> 79.302521 | J7: =Table1[[#This Row],[monthly_consumption_kwh]]*Table1[[#This Row],[NETTO_procurement_cost_ct_per_kwh]]/100 -> 64.1355 | K7: =Table1[[#This Row],[NETTO_monthly_revenue(€)]]-Table1[[#This Row],[procurement_cost_(€)]] -> 15.167021 | L7: =IF(F7=0,"",K7/F7*100) -> 5.99487 | M7: =TEXT(E7,"yyyy-mm") -> 22.05.2024 | N7: =G7/1.19 -> 79.302521
A8: C0007 | B8: 12 | C8: high | D8: Check24 | E8: 14.04.2024 | F8: 356 | G8: 118.13 | H8: 20.79 | I8: =Table1[[#This Row],[BRUTTO_monthly_bill_eur]]/1.19 -> 99.268908 | J8: =Table1[[#This Row],[monthly_consumption_kwh]]*Table1[[#This Row],[NETTO_procurement_cost_ct_per_kwh]]/100 -> 74.0124 | K8: =Table1[[#This Row],[NETTO_monthly_revenue(€)]]-Table1[[#This Row],[procurement_cost_(€)]] -> 25.256508 | L8: =IF(F8=0,"",K8/F8*100) -> 7.0945246 | M8: =TEXT(E8,"yyyy-mm") -> 14.04.2024 | N8: =G8/1.19 -> 99.268908
A9: C0008 | B9: 24 | C9: high | D9: Check24 | E9: 30.03.2024 | F9: 600 | G9: 201.44 | H9: 20.24 | I9: =Table1[[#This Row],[BRUTTO_monthly_bill_eur]]/1.19 -> 169.27731 | J9: =Table1[[#This Row],[monthly_consumption_kwh]]*Table1[[#This Row],[NETTO_procurement_cost_ct_per_kwh]]/100 -> 121.44 | K9: =Table1[[#This Row],[NETTO_monthly_revenue(€)]]-Table1[[#This Row],[procurement_cost_(€)]] -> 47.837311 | L9: =IF(F9=0,"",K9/F9*100) -> 7.9728852 | M9: =TEXT(E9,"yyyy-mm") -> 30.03.2024 | N9: =G9/1.19 -> 169.27731
A10: C0009 | B10: 24 | C10: mid | D10: Sales Representative | E10: 08.03.2025 | F10: 206 | G10: 81.82 | H10: 23.76 | I10: =Table1[[#This Row],[BRUTTO_monthly_bill_eur]]/1.19 -> 68.756303 | J10: =Table1[[#This Row],[monthly_consumption_kwh]]*Table1[[#This Row],[NETTO_procurement_cost_ct_per_kwh]]/100 -> 48.9456 | K10: =Table1[[#This Row],[NETTO_monthly_revenue(€)]]-Table1[[#This Row],[procurement_cost_(€)]] -> 19.810703 | L10: =IF(F10=0,"",K10/F10*100) -> 9.6168459 | M10: =TEXT(E10,"yyyy-mm") -> 08.03.2025 | N10: =G10/1.19 -> 68.756303
A11: C0010 | B11: 24 | C11: low | D11: Check24 | E11: 02.02.2024 | F11: 128 | G11: 56.66 | H11: 30.44 | I11: =Table1[[#This Row],[BRUTTO_monthly_bill_eur]]/1.19 -> 47.613445 | J11: =Table1[[#This Row],[monthly_consumption_kwh]]*Table1[[#This Row],[NETTO_procurement_cost_ct_per_kwh]]/100 -> 38.9632 | K11: =Table1[[#This Row],[NETTO_monthly_revenue(€)]]-Table1[[#This Row],[procurement_cost_(€)]] -> 8.6502454 | L11: =IF(F11=0,"",K11/F11*100) -> 6.7580042 | M11: =TEXT(E11,"yyyy-mm") -> 02.02.2024 | N11: =G11/1.19 -> 47.613445
A12: C0011 | B12: 12 | C12: high | D12: Website | E12: 31.01.2024 | F12: 627 | G12: 193.85 | H12: 17.3 | I12: =Table1[[#This Row],[BRUTTO_monthly_bill_eur]]/1.19 -> 162.89916 | J12: =Table1[[#This Row],[monthly_consumption_kwh]]*Table1[[#This Row],[NETTO_procurement_cost_ct_per_kwh]]/100 -> 108.471 | K12: =Table1[[#This Row],[NETTO_monthly_revenue(€)]]-Table1[[#This Row],[procurement_cost_(€)]] -> 54.42816 | L12: =IF(F12=0,"",K12/F12*100) -> 8.6807272 | M12: =TEXT(E12,"yyyy-mm") -> 31.01.2024 | N12: =G12/1.19 -> 162.89916
A13: C0012 | B13: 24 | C13: high | D13: Check24 | E13: 05.04.2024 | F13: 550 | G13: 185.06 | H13: 19.87 | I13: =Table1[[#This Row],[BRUTTO_monthly_bill_eur]]/1.19 -> 155.51261 | J13: =Table1[[#This Row],[monthly_consumption_kwh]]*Table1[[#This Row],[NETTO_procurement_cost_ct_per_kwh]]/100 -> 109.285 | K13: =Table1[[#This Row],[NETTO_monthly_revenue(€)]]-Table1[[#This Row],[procurement_cost_(€)]] -> 46.227605 | L13: =IF(F13=0,"",K13/F13*100) -> 8.4050191 | M13: =TEXT(E13,"yyyy-mm") -> 05.04.2024 | N13: =G13/1.19 -> 155.51261
... A801: C0800 | B801: 24 | C801: high | D801: Check24 | E801: 14.06.2025 | F801: 546 | G801: 187.61 | H801: 17.31 | I801: =Table1[[#This Row],[BRUTTO_monthly_bill_eur]]/1.19 -> 157.65546 | J801: =Table1[[#This Row],[monthly_consumption_kwh]]*Table1[[#This Row],[NETTO_procurement_cost_ct_per_kwh]]/100 -> 94.5126 | K801: =Table1[[#This Row],[NETTO_monthly_revenue(€)]]-Table1[[#This Row],[procurement_cost_(€)]] -> 63.142862 | L801: =IF(F801=0,"",K801/F801*100) -> 11.564627 | M801: =TEXT(E801,"yyyy-mm") -> 14.06.2025 | N801: =G801/1.19 -> 157.65546

Sheet Q3 Pivot_1
A3: Row Labels | B3: Sum of ptofit_(€)
A4: 12 | B4: -15878.976
A5: 24 | B5: 8906.7178
A6: Grand Total | B6: -6972.2579

Sheet Q3 Pivot_2
A3: Row Labels | B3: Average of ptofit_(€)
A4: Check24 | B4: 22.652564
A5: Sales Representative | B5: -61.376467
A6: Website | B6: -37.520222
A7: Grand Total | B7: -8.7153224

Sheet Q1_Prepare_Data
A1: customer_id | B1: contract_duration_months | C1: consumption_tier | D1: acquisition_channel | E1: contract_start_date | F1: monthly_consumption_kwh | G1: BRUTTO_monthly_bill_eur | H1: NETTO_procurement_cost_ct_per_kwh | I1: duplicate | J1: zero_consumption | K1: negative_consumption | L1: net_revenue
A2: C0001 | B2: 12 | C2: mid | D2: Check24 | E2: 24.04.2024 | F2: 199 | G2: 76.88 | H2: 24.21 | I2: =COUNTIF($A:$A,A2) -> 1 | J2: =IF(F2=0,"Yes","No") -> No | K2: =IF(F2<0,"Yes","No") -> No | L2: =G2/1.19 -> 64.605042
A3: C0002 | B3: 24 | C3: low | D3: Check24 | E3: 26.01.2024 | F3: 110 | G3: 49.75 | H3: 30.01 | I3: =COUNTIF($A:$A,A3) -> 1 | J3: =IF(F3=0,"Yes","No") -> No | K3: =IF(F3<0,"Yes","No") -> No | L3: =G3/1.19 -> 41.806723
A4: C0003 | B4: 24 | C4: mid | D4: Check24 | E4: 08.10.2024 | F4: 205 | G4: 85.14 | H4: 22.78 | I4: =COUNTIF($A:$A,A4) -> 1 | J4: =IF(F4=0,"Yes","No") -> No | K4: =IF(F4<0,"Yes","No") -> No | L4: =G4/1.19 -> 71.546218
A5: C0004 | B5: 24 | C5: mid | D5: Check24 | E5: 07.09.2024 | F5: 226 | G5: 84.24 | H5: 25.44 | I5: =COUNTIF($A:$A,A5) -> 1 | J5: =IF(F5=0,"Yes","No") -> No | K5: =IF(F5<0,"Yes","No") -> No | L5: =G5/1.19 -> 70.789916
A6: C0005 | B6: 12 | C6: mid | D6: Website | E6: 16.08.2024 | F6: 178 | G6: 70.68 | H6: 24.71 | I6: =COUNTIF($A:$A,A6) -> 1 | J6: =IF(F6=0,"Yes","No") -> No | K6: =IF(F6<0,"Yes","No") -> No | L6: =G6/1.19 -> 59.394958
A7: C0006 | B7: 12 | C7: mid | D7: Website | E7: 22.05.2024 | F7: 253 | G7: 94.37 | H7: 25.35 | I7: =COUNTIF($A:$A,A7) -> 1 | J7: =IF(F7=0,"Yes","No") -> No | K7: =IF(F7<0,"Yes","No") -> No | L7: =G7/1.19 -> 79.302521
A8: C0007 | B8: 12 | C8: high | D8: Check24 | E8: 14.04.2024 | F8: 356 | G8: 118.13 | H8: 20.79 | I8: =COUNTIF($A:$A,A8) -> 1 | J8: =IF(F8=0,"Yes","No") -> No | K8: =IF(F8<0,"Yes","No") -> No | L8: =G8/1.19 -> 99.268908
A9: C0008 | B9: 24 | C9: high | D9: Check24 | E9: 30.03.2024 | F9: 600 | G9: 201.44 | H9: 20.24 | I9: =COUNTIF($A:$A,A9) -> 1 | J9: =IF(F9=0,"Yes","No") -> No | K9: =IF(F9<0,"Yes","No") -> No | L9: =G9/1.19 -> 169.27731
A10: C0009 | B10: 24 | C10: mid | D10: Sales Representative | E10: 08.03.2025 | F10: 206 | G10: 81.82 | H10: 23.76 | I10: =COUNTIF($A:$A,A10) -> 1 | J10: =IF(F10=0,"Yes","No") -> No | K10: =IF(F10<0,"Yes","No") -> No | L10: =G10/1.19 -> 68.756303
A11: C0010 | B11: 24 | C11: low | D11: Check24 | E11: 02.02.2024 | F11: 128 | G11: 56.66 | H11: 30.44 | I11: =COUNTIF($A:$A,A11) -> 1 | J11: =IF(F11=0,"Yes","No") -> No | K11: =IF(F11<0,"Yes","No") -> No | L11: =G11/1.19 -> 47.613445
A12: C0011 | B12: 12 | C12: high | D12: Website | E12: 31.01.2024 | F12: 627 | G12: 193.85 | H12: 17.3 | I12: =COUNTIF($A:$A,A12) -> 1 | J12: =IF(F12=0,"Yes","No") -> No | K12: =IF(F12<0,"Yes","No") -> No | L12: =G12/1.19 -> 162.89916
A13: C0012 | B13: 24 | C13: high | D13: Check24 | E13: 05.04.2024 | F13: 550 | G13: 185.06 | H13: 19.87 | I13: =COUNTIF($A:$A,A13) -> 1 | J13: =IF(F13=0,"Yes","No") -> No | K13: =IF(F13<0,"Yes","No") -> No | L13: =G13/1.19 -> 155.51261
... A801: C0800 | B801: 24 | C801: high | D801: Check24 | E801: 14.06.2025 | F801: 546 | G801: 187.61 | H801: 17.31 | I801: =COUNTIF($A:$A,A801) -> 1 | J801: =IF(F801=0,"Yes","No") -> No | K801: =IF(F801<0,"Yes","No") -> No | L801: =G801/1.19 -> 157.65546

Sheet Q2_Customer_Profitability
A3: Customer_Id | B3: Sum of monthly_consumption_kwh | C3: Sum of Profit(€) | D3: Sum of Profit(ct/kWh) | G3: Observations
A4: C0001 | B4: 199 | C4: 16.427142 | D4: 8.2548452 | G4: 1. Higher consumption customers generate greater total profit because larger electricity usage increases revenue although higher procurement costs.
A5: C0002 | B5: 110 | C5: 8.7957227 | D5: 7.9961115 | G5: 2. Profit per kWh provides a fair comparison across customers since it measures the profit for each unit of electricity sold.
A6: C0003 | B6: 205 | C6: 24.847218 | D6: 12.120594 | G6: 3. A few customers have low or negative profitability, suggesting opportunities to review pricing strategies, or data quality.
A7: C0004 | B7: 226 | C7: 13.295516 | D7: 5.8829717
A8: C0005 | B8: 178 | C8: 15.411158 | D8: 8.6579539
A9: C0006 | B9: 253 | C9: 15.167021 | D9: 5.99487
A10: C0007 | B10: 356 | C10: 25.256508 | D10: 7.0945246
A11: C0008 | B11: 600 | C11: 47.837311 | D11: 7.9728852
A12: C0009 | B12: 206 | C12: 19.810703 | D12: 9.6168459
A13: C0010 | B13: 128 | C13: 8.6502454 | D13: 6.7580042
A14: C0011 | B14: 627 | C14: 54.42816 | D14: 8.6807272
A15: C0012 | B15: 550 | C15: 46.227605 | D15: 8.4050191
A16: C0013 | B16: 128 | C16: 9.7426017 | D16: 7.6114076
A17: C0014 | B17: 441 | C17: 32.663392 | D17: 7.406665
A18: C0015 | B18: 444 | C18: 50.070975 | D18: 11.277247
... A801: Grand Total | B801: 303265 | C801: -6972.2579 | D801: 4187.8552

Sheet Q3_Summary
C1: KPI | D1: Value | K1: Observations
C2: Total Customers | D2: =COUNTA(_xlfn.UNIQUE(Data!A2:A801)) -> 797 | K2: The Dataset contain total 800 contracts, having 797 unique customer due to three duplicates customer ID.
C3: Total Contracts | D3: =COUNTA(Data!A2:A801) -> 800
C4: Avg Monthly Consumption(kWh) | D4: =AVERAGE(Data!F2:F801) -> 379.08125 | K4: Average monthly consumption is 379.08 kWh, with an average monthly bill of €98.89.
C5: Avg Monthly Bill(€) | D5: =AVERAGE(Data!G2:G801) -> 98.88905 | K5: Although the average profit is -€8.72, the median profit is €18.22, suggesting that most customers are profitable.
C6: Avg Procurement Cost(cents/kWh) | D6: =AVERAGE(Data!H2:H801) -> 24.904725 | K6: The extremely low profit (-€13,668.20) appears to be an outlier that significantly reduces the overall average.
C7: Avg Profit(€) | D7: =AVERAGE(Data!K2:K801) -> -8.7153224 | K7: Further investigation of these extreme negative-profit contracts is recommended before drawing pricing conclusions.
C8: Median profit(€) | D8: =MEDIAN(Data!K2:K801) -> 18.218046
C9: Highest profit(€) | D9: =MAX(Data!K2:K801) -> 172.65081
C10: Lowest Profit(€) | D10: =MIN(Data!K2:K801) -> -13668.202
A13: Average Profit by Contract Duration | K13: Observations
A14: Contract Duration in Months | B14: Average of ptofit_(€) | K14: Customer having 24- months(fix24) contract are generating higher profit than customers with 12-months(fix12) contract.
A15: 12 | B15: -36.006748
A16: 24 | B16: 24.809799
A30: Average Profit by Aquisition Channel | K30: Observations
A31: Acquisition Channel | B31: Average of ptofit_(€) | K31: Customer aquired from Check24 channel are more profitable whie customers aquird from other channel has the lowest average profit.
A32: Check24 | B32: 22.652564
A33: Sales Representative | B33: -61.376467
A34: Website | B34: -37.520222
A47: Average Profit by Consumption Tier | K47: Observations
A48: Consumption Tier | B48: Average of ptofit_(€) | K48: Higher consumption customer generates higher average monthly profit, making them valuable for retention.
A49: high | B49: 48.082204
A50: low | B50: -39.920771
A51: mid | B51: -16.03292

Sheet Q4_Contract_Start_Month
A3: Contract Start Month | B3: Average of Profit(€) | M3: Observation
A4: January | B4: 24.90596 | M4: Average profitability is relatively stable across months, ranging between approximately €22 and €25. However, contracts starting in June show a significantly lower average profit of -€376.15, making June a clear outlier.
A5: February | B5: 22.821204
A6: March | B6: 22.707507 | M6: Business Hypothesis
A7: April | B7: 22.209904 | M7: 1. Seasonal marketing campaigns or promotional discounts may have reduced profitability during summer months.
A8: May | B8: 22.660271 | M8: 2. Electricity procurement costs may have been lower during certain months, resulting in higher margins.
A9: June | B9: -376.15252
A10: July | B10: 23.823666
A11: August | B11: 24.660871
A12: September | B12: 23.073238
A13: October | B13: 23.394493
A14: November | B14: 23.674891
A15: December | B15: 22.058276

Sheet Q5_Customer_Groups
A1: Average Profit by Aquisition Channel | M1: Observation
A2: Acquisition Channel | B2: Average of Profit(€) | M2: Customer aquired from Check24 channel are more profitable whie customers aquird from other channel has the lowest average profit.
A3: Check24 | B3: 22.652564
A4: Sales Representative | B4: -61.376467
A5: Website | B5: -37.520222 | M5: Hypthesis
M6: Check24 may attract more profitable customers, while Sales Representative and Website channels may involve higher acquisition costs or discounts, leading to lower average profitability.
A17: Average Profit by Consumption Tier | M17: Observation
A18: Consumption Tier | B18: Average of Profit(€) | M18: Higher consumption customer generates higher average monthly profit, making them valuable for retention.
A19: high | B19: 48.082204
A20: low | B20: -39.920771
A21: mid | B21: -16.03292 | M21: Hypothesis
M22: Customers with higher electricity usage generate more revenue each month. Although procurement costs also increase, the higher revenue may result in greater overall profit.
A33: Average Profit by Contract Duration | M33: Observation
A34: Contract Duration | B34: Average of Profit(€) | M34: Customer having 24- months(fix24) contract are generating higher profit than customers with 12-months(fix12) contract.
A35: 12 | B35: -36.006748
A36: 24 | B36: 24.809799
M37: Hypothesis
M38: Customers with longer contracts remain with the company for a longer period, providing more stable revenue and reducing the costs associated with frequent customer acquisition.

Sheet Data_Q4_Q5
A1: customer_id | B1: contract_duration_months | C1: consumption_tier | D1: acquisition_channel | E1: contract_start_date | F1: monthly_consumption_kwh | G1: BRUTTO_monthly_bill_eur | H1: NETTO_procurement_cost_ct_per_kwh | I1: net_revenue_(€) | J1: procurement_cost_(€) | K1: Profit(€) | L1: Profit(ct/kWh) | M1: contract_start_month
A2: C0001 | B2: 12 | C2: mid | D2: Check24 | E2: 24.04.2024 | F2: 199 | G2: 76.88 | H2: 24.21 | I2: =G2/1.19 -> 64.605042 | J2: =F2*H2/100 -> 48.1779 | K2: =I2-J2 -> 16.427142 | L2: =IF(F2=0,"",K2/F2*100) -> 8.2548452 | M2: =TEXT(DATE(RIGHT(E2,4),MID(E2,4,2),LEFT(E2,2)),"mmmm") -> April
A3: C0002 | B3: 24 | C3: low | D3: Check24 | E3: 26.01.2024 | F3: 110 | G3: 49.75 | H3: 30.01 | I3: =G3/1.19 -> 41.806723 | J3: =F3*H3/100 -> 33.011 | K3: =I3-J3 -> 8.7957227 | L3: =IF(F3=0,"",K3/F3*100) -> 7.9961115 | M3: =TEXT(DATE(RIGHT(E3,4),MID(E3,4,2),LEFT(E3,2)),"mmmm") -> January
A4: C0003 | B4: 24 | C4: mid | D4: Check24 | E4: 45514 | F4: 205 | G4: 85.14 | H4: 22.78 | I4: =G4/1.19 -> 71.546218 | J4: =F4*H4/100 -> 46.699 | K4: =I4-J4 -> 24.847218 | L4: =IF(F4=0,"",K4/F4*100) -> 12.120594 | M4: =TEXT(DATE(RIGHT(E4,4),MID(E4,4,2),LEFT(E4,2)),"mmmm") -> March
A5: C0004 | B5: 24 | C5: mid | D5: Check24 | E5: 45482 | F5: 226 | G5: 84.24 | H5: 25.44 | I5: =G5/1.19 -> 70.789916 | J5: =F5*H5/100 -> 57.4944 | K5: =I5-J5 -> 13.295516 | L5: =IF(F5=0,"",K5/F5*100) -> 5.8829717 | M5: =TEXT(DATE(RIGHT(E5,4),MID(E5,4,2),LEFT(E5,2)),"mmmm") -> November
A6: C0005 | B6: 12 | C6: mid | D6: Website | E6: 16.08.2024 | F6: 178 | G6: 70.68 | H6: 24.71 | I6: =G6/1.19 -> 59.394958 | J6: =F6*H6/100 -> 43.9838 | K6: =I6-J6 -> 15.411158 | L6: =IF(F6=0,"",K6/F6*100) -> 8.6579539 | M6: =TEXT(DATE(RIGHT(E6,4),MID(E6,4,2),LEFT(E6,2)),"mmmm") -> August
A7: C0006 | B7: 12 | C7: mid | D7: Website | E7: 22.05.2024 | F7: 253 | G7: 94.37 | H7: 25.35 | I7: =G7/1.19 -> 79.302521 | J7: =F7*H7/100 -> 64.1355 | K7: =I7-J7 -> 15.167021 | L7: =IF(F7=0,"",K7/F7*100) -> 5.99487 | M7: =TEXT(DATE(RIGHT(E7,4),MID(E7,4,2),LEFT(E7,2)),"mmmm") -> May
A8: C0007 | B8: 12 | C8: high | D8: Check24 | E8: 14.04.2024 | F8: 356 | G8: 118.13 | H8: 20.79 | I8: =G8/1.19 -> 99.268908 | J8: =F8*H8/100 -> 74.0124 | K8: =I8-J8 -> 25.256508 | L8: =IF(F8=0,"",K8/F8*100) -> 7.0945246 | M8: =TEXT(DATE(RIGHT(E8,4),MID(E8,4,2),LEFT(E8,2)),"mmmm") -> April
A9: C0008 | B9: 24 | C9: high | D9: Check24 | E9: 30.03.2024 | F9: 600 | G9: 201.44 | H9: 20.24 | I9: =G9/1.19 -> 169.27731 | J9: =F9*H9/100 -> 121.44 | K9: =I9-J9 -> 47.837311 | L9: =IF(F9=0,"",K9/F9*100) -> 7.9728852 | M9: =TEXT(DATE(RIGHT(E9,4),MID(E9,4,2),LEFT(E9,2)),"mmmm") -> March
A10: C0009 | B10: 24 | C10: mid | D10: Sales Representative | E10: 45872 | F10: 206 | G10: 81.82 | H10: 23.76 | I10: =G10/1.19 -> 68.756303 | J10: =F10*H10/100 -> 48.9456 | K10: =I10-J10 -> 19.810703 | L10: =IF(F10=0,"",K10/F10*100) -> 9.6168459 | M10: =TEXT(DATE(RIGHT(E10,4),MID(E10,4,2),LEFT(E10,2)),"mmmm") -> January
A11: C0010 | B11: 24 | C11: low | D11: Check24 | E11: 45324 | F11: 128 | G11: 56.66 | H11: 30.44 | I11: =G11/1.19 -> 47.613445 | J11: =F11*H11/100 -> 38.9632 | K11: =I11-J11 -> 8.6502454 | L11: =IF(F11=0,"",K11/F11*100) -> 6.7580042 | M11: =TEXT(DATE(RIGHT(E11,4),MID(E11,4,2),LEFT(E11,2)),"mmmm") -> January
A12: C0011 | B12: 12 | C12: high | D12: Website | E12: 31.01.2024 | F12: 627 | G12: 193.85 | H12: 17.3 | I12: =G12/1.19 -> 162.89916 | J12: =F12*H12/100 -> 108.471 | K12: =I12-J12 -> 54.42816 | L12: =IF(F12=0,"",K12/F12*100) -> 8.6807272 | M12: =TEXT(DATE(RIGHT(E12,4),MID(E12,4,2),LEFT(E12,2)),"mmmm") -> January
A13: C0012 | B13: 24 | C13: high | D13: Check24 | E13: 45416 | F13: 550 | G13: 185.06 | H13: 19.87 | I13: =G13/1.19 -> 155.51261 | J13: =F13*H13/100 -> 109.285 | K13: =I13-J13 -> 46.227605 | L13: =IF(F13=0,"",K13/F13*100) -> 8.4050191 | M13: =TEXT(DATE(RIGHT(E13,4),MID(E13,4,2),LEFT(E13,2)),"mmmm") -> May
A14: C0013 | B14: 24 | C14: low | D14: Check24 | E14: 45604 | F14: 128 | G14: 55.34 | H14: 28.72 | I14: =G14/1.19 -> 46.504202 | J14: =F14*H14/100 -> 36.7616 | K14: =I14-J14 -> 9.7426017 | L14: =IF(F14=0,"",K14/F14*100) -> 7.6114076 | M14: =TEXT(DATE(RIGHT(E14,4),MID(E14,4,2),LEFT(E14,2)),"mmmm") -> May
A15: C0014 | B15: 12 | C15: high | D15: Check24 | E15: 26.08.2024 | F15: 441 | G15: 143.67 | H15: 19.97 | I15: =G15/1.19 -> 120.73109 | J15: =F15*H15/100 -> 88.0677 | K15: =I15-J15 -> 32.663392 | L15: =IF(F15=0,"",K15/F15*100) -> 7.406665 | M15: =TEXT(DATE(RIGHT(E15,4),MID(E15,4,2),LEFT(E15,2)),"mmmm") -> August
A16: C0015 | B16: 12 | C16: high | D16: Check24 | E16: 45663 | F16: 444 | G16: 152.84 | H16: 17.65 | I16: =G16/1.19 -> 128.43697 | J16: =F16*H16/100 -> 78.366 | K16: =I16-J16 -> 50.070975 | L16: =IF(F16=0,"",K16/F16*100) -> 11.277247 | M16: =TEXT(DATE(RIGHT(E16,4),MID(E16,4,2),LEFT(E16,2)),"mmmm") -> April
A17: C0016 | B17: 12 | C17: mid | D17: Sales Representative | E17: 28.01.2024 | F17: 278 | G17: 104.25 | H17: 22.47 | I17: =G17/1.19 -> 87.605042 | J17: =F17*H17/100 -> 62.4666 | K17: =I17-J17 -> 25.138442 | L17: =IF(F17=0,"",K17/F17*100) -> 9.042605 | M17: =TEXT(DATE(RIGHT(E17,4),MID(E17,4,2),LEFT(E17,2)),"mmmm") -> January
A18: C0017 | B18: 12 | C18: mid | D18: Check24 | E18: 45495 | F18: 332 | G18: 129.06 | H18: 22.66 | I18: =G18/1.19 -> 108.45378 | J18: =F18*H18/100 -> 75.2312 | K18: =I18-J18 -> 33.222582 | L18: =IF(F18=0,"",K18/F18*100) -> 10.006802 | M18: =TEXT(DATE(RIGHT(E18,4),MID(E18,4,2),LEFT(E18,2)),"mmmm") -> December
A19: C0018 | B19: 12 | C19: mid | D19: Check24 | E19: 45780 | F19: 277 | G19: 109.61 | H19: 22.01 | I19: =G19/1.19 -> 92.109244 | J19: =F19*H19/100 -> 60.9677 | K19: =I19-J19 -> 31.141544 | L19: =IF(F19=0,"",K19/F19*100) -> 11.242435 | M19: =TEXT(DATE(RIGHT(E19,4),MID(E19,4,2),LEFT(E19,2)),"mmmm") -> September
A20: C0019 | B20: 12 | C20: low | D20: Check24 | E20: 13.08.2024 | F20: 130 | G20: 58.4 | H20: 30.87 | I20: =G20/1.19 -> 49.07563 | J20: =F20*H20/100 -> 40.131 | K20: =I20-J20 -> 8.9446303 | L20: =IF(F20=0,"",K20/F20*100) -> 6.8804848 | M20: =TEXT(DATE(RIGHT(E20,4),MID(E20,4,2),LEFT(E20,2)),"mmmm") -> August
A21: C0020 | B21: 12 | C21: low | D21: Check24 | E21: 45751 | F21: 144 | G21: 59.77 | H21: 30.93 | I21: =G21/1.19 -> 50.226891 | J21: =F21*H21/100 -> 44.5392 | K21: =I21-J21 -> 5.6876908 | L21: =IF(F21=0,"",K21/F21*100) -> 3.9497852 | M21: =TEXT(DATE(RIGHT(E21,4),MID(E21,4,2),LEFT(E21,2)),"mmmm") -> April
A22: C0021 | B22: 24 | C22: high | D22: Check24 | E22: 45606 | F22: 488 | G22: 163.32 | H22: 19.07 | I22: =G22/1.19 -> 137.2437 | J22: =F22*H22/100 -> 93.0616 | K22: =I22-J22 -> 44.182097 | L22: =IF(F22=0,"",K22/F22*100) -> 9.0537085 | M22: =TEXT(DATE(RIGHT(E22,4),MID(E22,4,2),LEFT(E22,2)),"mmmm") -> July
A23: C0022 | B23: 12 | C23: low | D23: Check24 | E23: 45474 | F23: 88 | G23: 41.01 | H23: 28.65 | I23: =G23/1.19 -> 34.462185 | J23: =F23*H23/100 -> 25.212 | K23: =I23-J23 -> 9.2501849 | L23: =IF(F23=0,"",K23/F23*100) -> 10.511574 | M23: =TEXT(DATE(RIGHT(E23,4),MID(E23,4,2),LEFT(E23,2)),"mmmm") -> March
A24: C0023 | B24: 12 | C24: low | D24: Website | E24: 45632 | F24: 130 | G24: 57.83 | H24: 30.33 | I24: =G24/1.19 -> 48.596639 | J24: =F24*H24/100 -> 39.429 | K24: =I24-J24 -> 9.1676387 | L24: =IF(F24=0,"",K24/F24*100) -> 7.0520297 | M24: =TEXT(DATE(RIGHT(E24,4),MID(E24,4,2),LEFT(E24,2)),"mmmm") -> September
A25: C0024 | B25: 12 | C25: mid | D25: Check24 | E25: 45872 | F25: 326 | G25: 123.81 | H25: 22.08 | I25: =G25/1.19 -> 104.04202 | J25: =F25*H25/100 -> 71.9808 | K25: =I25-J25 -> 32.061217 | L25: =IF(F25=0,"",K25/F25*100) -> 9.8347291 | M25: =TEXT(DATE(RIGHT(E25,4),MID(E25,4,2),LEFT(E25,2)),"mmmm") -> January
A26: C0025 | B26: 12 | C26: mid | D26: Check24 | E26: 14.12.2024 | F26: 196 | G26: 78.67 | H26: 22.66 | I26: =G26/1.19 -> 66.109244 | J26: =F26*H26/100 -> 44.4136 | K26: =I26-J26 -> 21.695644 | L26: =IF(F26=0,"",K26/F26*100) -> 11.069206 | M26: =TEXT(DATE(RIGHT(E26,4),MID(E26,4,2),LEFT(E26,2)),"mmmm") -> December
A27: C0026 | B27: 24 | C27: high | D27: Sales Representative | E27: 45606 | F27: 564 | G27: 194.49 | H27: 20.95 | I27: =G27/1.19 -> 163.43697 | J27: =F27*H27/100 -> 118.158 | K27: =I27-J27 -> 45.278975 | L27: =IF(F27=0,"",K27/F27*100) -> 8.028187 | M27: =TEXT(DATE(RIGHT(E27,4),MID(E27,4,2),LEFT(E27,2)),"mmmm") -> July
A28: C0027 | B28: 12 | C28: low | D28: Check24 | E28: 45510 | F28: 100 | G28: 47.51 | H28: 30.97 | I28: =G28/1.19 -> 39.92437 | J28: =F28*H28/100 -> 30.97 | K28: =I28-J28 -> 8.9543697 | L28: =IF(F28=0,"",K28/F28*100) -> 8.9543697 | M28: =TEXT(DATE(RIGHT(E28,4),MID(E28,4,2),LEFT(E28,2)),"mmmm") -> November
A29: C0028 | B29: 12 | C29: low | D29: Sales Representative | E29: 45512 | F29: 128 | G29: 53.68 | H29: 29.42 | I29: =G29/1.19 -> 45.109244 | J29: =F29*H29/100 -> 37.6576 | K29: =I29-J29 -> 7.4516437 | L29: =IF(F29=0,"",K29/F29*100) -> 5.8215966 | M29: =TEXT(DATE(RIGHT(E29,4),MID(E29,4,2),LEFT(E29,2)),"mmmm") -> January
A30: C0029 | B30: 24 | C30: mid | D30: Check24 | E30: 45577 | F30: 183 | G30: 74.61 | H30: 22.42 | I30: =G30/1.19 -> 62.697479 | J30: =F30*H30/100 -> 41.0286 | K30: =I30-J30 -> 21.668879 | L30: =IF(F30=0,"",K30/F30*100) -> 11.840917 | M30: =TEXT(DATE(RIGHT(E30,4),MID(E30,4,2),LEFT(E30,2)),"mmmm") -> June
A31: C0030 | B31: 12 | C31: mid | D31: Sales Representative | E31: 14.04.2024 | F31: 242 | G31: 91.27 | H31: 22.89 | I31: =G31/1.19 -> 76.697479 | J31: =F31*H31/100 -> 55.3938 | K31: =I31-J31 -> 21.303679 | L31: =IF(F31=0,"",K31/F31*100) -> 8.8031731 | M31: =TEXT(DATE(RIGHT(E31,4),MID(E31,4,2),LEFT(E31,2)),"mmmm") -> April
A32: C0031 | B32: 24 | C32: low | D32: Website | E32: 45386 | F32: 146 | G32: 65.63 | H32: 30.08 | I32: =G32/1.19 -> 55.151261 | J32: =F32*H32/100 -> 43.9168 | K32: =I32-J32 -> 11.234461 | L32: =IF(F32=0,"",K32/F32*100) -> 7.694836 | M32: =TEXT(DATE(RIGHT(E32,4),MID(E32,4,2),LEFT(E32,2)),"mmmm") -> March
A33: C0032 | B33: 12 | C33: mid | D33: Sales Representative | E33: 24.01.2025 | F33: 225 | G33: 86.07 | H33: 24.43 | I33: =G33/1.19 -> 72.327731 | J33: =F33*H33/100 -> 54.9675 | K33: =I33-J33 -> 17.360231 | L33: =IF(F33=0,"",K33/F33*100) -> 7.7156583 | M33: =TEXT(DATE(RIGHT(E33,4),MID(E33,4,2),LEFT(E33,2)),"mmmm") -> January
A34: C0033 | B34: 12 | C34: low | D34: Sales Representative | E34: 45539 | F34: 139 | G34: 59.27 | H34: 28.98 | I34: =G34/1.19 -> 49.806723 | J34: =F34*H34/100 -> 40.2822 | K34: =I34-J34 -> 9.5245227 | L34: =IF(F34=0,"",K34/F34*100) -> 6.8521746 | M34: =TEXT(DATE(RIGHT(E34,4),MID(E34,4,2),LEFT(E34,2)),"mmmm") -> April
A35: C0034 | B35: 24 | C35: low | D35: Check24 | E35: 45689 | F35: 150 | G35: 65.48 | H35: 28.23 | I35: =G35/1.19 -> 55.02521 | J35: =F35*H35/100 -> 42.345 | K35: =I35-J35 -> 12.68021 | L35: =IF(F35=0,"",K35/F35*100) -> 8.4534734 | M35: =TEXT(DATE(RIGHT(E35,4),MID(E35,4,2),LEFT(E35,2)),"mmmm") -> June
A36: C0035 | B36: 24 | C36: mid | D36: Sales Representative | E36: 18.12.2024 | F36: 321 | G36: 117.03 | H36: 23.56 | I36: =G36/1.19 -> 98.344538 | J36: =F36*H36/100 -> 75.6276 | K36: =I36-J36 -> 22.716938 | L36: =IF(F36=0,"",K36/F36*100) -> 7.0769277 | M36: =TEXT(DATE(RIGHT(E36,4),MID(E36,4,2),LEFT(E36,2)),"mmmm") -> December
A37: C0036 | B37: 24 | C37: mid | D37: Check24 | E37: 27.09.2024 | F37: 206 | G37: 83.4 | H37: 22.94 | I37: =G37/1.19 -> 70.084034 | J37: =F37*H37/100 -> 47.2564 | K37: =I37-J37 -> 22.827634 | L37: =IF(F37=0,"",K37/F37*100) -> 11.081376 | M37: =TEXT(DATE(RIGHT(E37,4),MID(E37,4,2),LEFT(E37,2)),"mmmm") -> September
A38: C0037 | B38: 12 | C38: high | D38: Check24 | E38: 14.02.2024 | F38: 466 | G38: 163.56 | H38: 17.6 | I38: =G38/1.19 -> 137.44538 | J38: =F38*H38/100 -> 82.016 | K38: =I38-J38 -> 55.429378 | L38: =IF(F38=0,"",K38/F38*100) -> 11.894716 | M38: =TEXT(DATE(RIGHT(E38,4),MID(E38,4,2),LEFT(E38,2)),"mmmm") -> February
A39: C0038 | B39: 12 | C39: mid | D39: Check24 | E39: 15.04.2025 | F39: 192 | G39: 77.57 | H39: 25.84 | I39: =G39/1.19 -> 65.184874 | J39: =F39*H39/100 -> 49.6128 | K39: =I39-J39 -> 15.572074 | L39: =IF(F39=0,"",K39/F39*100) -> 8.1104552 | M39: =TEXT(DATE(RIGHT(E39,4),MID(E39,4,2),LEFT(E39,2)),"mmmm") -> April
A40: C0039 | B40: 24 | C40: mid | D40: Check24 | E40: 45478 | F40: 332 | G40: 124.14 | H40: 24.47 | I40: =G40/1.19 -> 104.31933 | J40: =F40*H40/100 -> 81.2404 | K40: =I40-J40 -> 23.078928 | L40: =IF(F40=0,"",K40/F40*100) -> 6.9514843 | M40: =TEXT(DATE(RIGHT(E40,4),MID(E40,4,2),LEFT(E40,2)),"mmmm") -> July
...
